<!--<xacro:property name="R" value="2" />-->
<mujoco model="Rabbit">
  <compiler angle="radian" coordinate="local" inertiafromgeom="false"/>
  <default>
    <joint armature="0" damping="0" limited="false"/>
    <geom conaffinity="0" condim="3" contype="1" density="1000" friction=".7 .1 .1" rgba="0.8 0.6 .4 1"/>
  </default>
  <option integrator="Euler" timestep="0.002" solver="Newton"/>
  <worldbody>
    <light cutoff="100" diffuse="1 1 1" dir="-0 0 -1.3" directional="true" exponent="1" pos="0 0 1.3" specular=".1 .1 .1"/>
    <geom conaffinity="1" condim="3" name="floor" pos="0 0 0" rgba="0.8 0.9 0.8 1" size="40 40 40" type="plane" material="MatPlane"/>
    <body name="torso" pos="0 0 0">
      <inertial mass="12" pos = "0 0 0.24" fullinertia = "0.001 0.001 0.001 0 0 0"/>
      <camera name="track" mode="trackcom" pos="0 -3 1" xyaxes="1 0 0 0 0 1"/>
      <joint armature="0" axis="1 0 0" damping="0" limited="false" name="rootx" pos="0 0 0" stiffness="0" type="slide"/>
      <joint armature="0" axis="0 0 1" damping="0" limited="false" name="rootz" pos="0 0 0" stiffness="0" type="slide"/>
      <joint armature="0" axis="0 1 0" damping="0" limited="false" name="rooty" pos="0 0 0" stiffness="0" type="hinge"/>
      <geom friction="0.9" fromto="0 0 0 0 0 0.5" name="torso_geom" size="0.05" type="capsule"/>
      <body name="left_thigh" pos="0 0.1 0">
        <inertial mass = "6.8" pos = "0 0 -0.11" fullinertia = "0.001 0.001 0.001 0 0 0"/>
<!--        <joint axis="0 -1 0" name="left_thigh_joint" pos="0 0 0" type="hinge" limited="true" range = ""/>-->
        <joint axis="0 -1 0" name="left_thigh_joint" pos="0 0 0" type="hinge" limited="true" range = "-10 10" damping = "0"/>
<!--        <joint axis="0 -1 0" name="left_thigh_joint" pos="0 0 0" type="hinge"/>-->
        <geom friction="0.9" fromto="0 0 -0.4 0 0 0" name="left_thigh_geom" size="0.05" type="capsule" rgba =  "1 0 0 1"/>
        <body name="left_shin" pos="0 0 -0.4">
          <inertial mass = "3.2"  pos = "0 0 -0.24" fullinertia = "0.001 0.001 0.001 0 0 0"/>
          <joint axis="0 -1 0" name="left_knee_joint" pos="0 0 0" type="hinge" limited="true" range = "-10 10" damping = "0" />
<!--          <joint axis="0 -1 0" name="left_knee_joint" pos="0 0 0" type="hinge" />-->
          <geom friction="0.9" fromto="0 0 -0.4 0 0 0" name="left_shin_geom" size="0.05" type="capsule" rgba =  "1 0 0 1"/>
        </body>
      </body>
      <!-- copied and then replace thigh->thigh_left, leg->leg_left, foot->foot_right -->
      <body name="right_thigh" pos="0 -0.1 0">
        <inertial mass = "6.8" pos = "0 0 -0.11" fullinertia = "0.001 0.001 0.001 0 0 0"/>
        <joint axis="0 -1 0" name="right_thigh_joint" pos="0 0 0" type="hinge" limited="true" range = "-10 10" damping = "0" />
<!--        <joint axis="0 -1 0" name="right_thigh_joint" pos="0 0 0" type="hinge" />-->
        <geom friction="0.9" fromto="0 0 -0.4 0 0 0" name="right_thigh_geom" size="0.05" type="capsule" rgba =  "0 0 1 1"/>
        <body name="right_shin" pos="0 0 -0.4">
          <inertial mass = "3.2" pos = "0 0 -0.24" fullinertia = "0.001 0.001 0.001 0 0 0"/>
          <joint axis="0 -1 0" name="right_knee_joint" pos="0 0 0" type="hinge" limited="true" range = "-10 10" damping = "0"/>
<!--          <joint axis="0 -1 0" name="right_knee_joint" pos="0 0 0" type="hinge"/>-->
          <geom friction="0.9" fromto="0 0 -0.4 0 0 0" name="right_shin_geom" size="0.05" type="capsule" rgba =  "0 0 1 1"/>
        </body>
      </body>
    </body>
  </worldbody>
  <actuator>
    <!-- <motor joint="torso_joint" ctrlrange="-100.0 100.0" isctrllimited="true"/>-->

    <motor joint="left_thigh_joint"/>
    <motor joint="left_knee_joint"/>
    <motor joint="right_thigh_joint"/>
    <motor joint="right_knee_joint"/>
<!--    <motor ctrllimited="true" ctrlrange="-1000.0 1000.0" joint="rootz" gear="1"/>-->
    <!-- <motor joint="finger2_rot" ctrlrange="-20.0 20.0" isctrllimited="true"/>-->
  </actuator>

<!--  <equality>-->
<!--    <weld name = "torso_weld" body1 = "torso" />-->
<!--  </equality>-->
    <asset>
        <texture type="skybox" builtin="gradient" rgb1=".4 .5 .6" rgb2="0 0 0"
            width="100" height="100"/>
        <texture builtin="flat" height="1278" mark="cross" markrgb="1 1 1" name="texgeom" random="0.01" rgb1="0.8 0.6 0.4" rgb2="0.8 0.6 0.4" type="cube" width="127"/>
        <texture builtin="checker" height="100" name="texplane" rgb1="0 0 0" rgb2="0.8 0.8 0.8" type="2d" width="100"/>
        <material name="MatPlane" reflectance="0.5" shininess="1" specular="1" texrepeat="60 60" texture="texplane"/>
        <material name="geom" texture="texgeom" texuniform="true"/>
    </asset>
</mujoco>
